# An Introduction to Exceptions

## Basic exception handling

|Description|Example|
|---|---|
|Java provides a robust mechanism for handling exceptions using the try, catch, and finally blocks.|1. 1<br><br>1. public class ExceptionExample {   <br>      public static void main(String[] args) {   <br>        int numerator = 10;   <br>        int denominator = 0; // This will cause an ArithmeticException   <br>        try {   <br>          int result = numerator / denominator; // This line may throw an exception   <br>          System.out.println("Result: " + result);   <br>        } catch (ArithmeticException e) {   <br>          System.out.println("Error: Cannot divide by zero.");   <br>      } finally {   <br>          System.out.println("This block executes regardless of an exception.");   <br>       }   <br>      }   <br>    } <br><br>Copied!Wrap Toggled!|

## Creating custom exceptions

| Description                                                                                                   | Example                                                                                                                                                                                                                                                                                                                                                                                                                                                                                                                                                                                                        |
| ------------------------------------------------------------------------------------------------------------- | -------------------------------------------------------------------------------------------------------------------------------------------------------------------------------------------------------------------------------------------------------------------------------------------------------------------------------------------------------------------------------------------------------------------------------------------------------------------------------------------------------------------------------------------------------------------------------------------------------------- |
| Sometimes, you may want to create your own exception types. You can do this by extending the Exception class. | 1. 1<br><br>1. class MyCustomException extends Exception {    <br>      public MyCustomException(String message) {    <br>        super(message); // Pass the message to the parent Exception class    <br>      }   <br>    }   <br>    public class CustomExceptionExample {    <br>       public static void main(String[] args) {    <br>     try {    <br>       throw new MyCustomException("This is a custom exception message.");    <br>     } catch (MyCustomException e) {    <br>       System.out.println(e.getMessage());    <br>       }   <br>      }   <br>    } <br><br>Copied!Wrap Toggled! |
# Using Finally Block

## The structure of exception-handling

|Description|Example|
|---|---|
|One important feature of Java is its exception handling mechanism, which includes the try, catch, and finally blocks.|1. 1<br><br>1. try {   <br>       // Code that may throw an exception    <br>    } catch (ExceptionType e) {    <br>       // Code to handle the exception    <br>    } finally {    <br>       // Code that will always execute   <br>    } <br><br>Copied!Wrap Toggled!|

## Understanding the finally block

|Description|Example|
|---|---|
|The code within the finally block always runs after the try and catch blocks, regardless of whether an exception was thrown or caught. It is commonly used for resource management.|1. 1<br><br>1. public class FinallyExample {    <br>      public static void main(String[] args) {     <br>        try {    <br>          System.out.println("In try block");    <br>        } catch (ArithmeticException e) {     <br>          int result = 10 / 0; // This line will throw an exception     <br>       } catch (ArithmeticException e) {    <br>          System.out.println("Caught an exception: " + e.getMessage());     <br>       } finally {     <br>     System.out.println("Finally block executed");      <br>       }   <br>      }   <br>    } <br><br>Copied!Wrap Toggled!|

## Correct usage of the finally block

|Description|Example|
|---|---|
|Always executing cleanup code: The primary purpose of the finally block is to ensure that the cleanup code runs regardless of whether an exception was thrown or not.|1. 1<br><br>1. public class CorrectFinallyUsage {     <br>      public static void main(String[] args) {     <br>        FileReader file = null;     <br>        try {    <br>          file = new FileReader("example.txt");   <br>          // Code to read from the file     <br>        } catch (IOException e) {    <br>        System.out.println("Error reading file: " + e.getMessage());      <br>       } finally {     <br>           try {     <br>             if (file != null) {   <br>               file.close();   <br>         System.out.println("File closed successfully.");   <br>             }   <br>         } catch (IOException e) {   <br>              System.out.println("Error closing file: " + e.getMessage());   <br>       }   <br>      }   <br>    } <br><br>Copied!Wrap Toggled!|
|Releasing database connections: Using the finally block to close database connections is another correct practice.|1. 1<br><br>1. import java.sql.Connection;     <br>    import java.sql.DriverManager;    <br>    import java.sql.SQLException;   <br>    public class DatabaseConnectionCorrectUsage {    <br>      public static void main(String[] args) {   <br>         Connection connection = null;      <br>         try {     <br>           connection = DriverManager.getConnection("jdbc![:mysql:](https://www.webpagefx.com/tools/emoji-cheat-sheet/graphics/emojis/mysql.png ":mysql:")//localhost:3306/mydb", "user", "password");     <br>           // Perform database operations      <br>         } catch (SQLException e) {    <br>               System.out.println("Database error: " + e.getMessage());    <br>         } finally {    <br>       try {          <br>         if (connection != null) {    <br>              connection.close();    <br>              System.out.println("Database connection closed.");    <br>          }   <br>       } catch (SQLException e) {   <br>          System.out.println("Error closing connection: " + e.getMessage());   <br>       }   <br>      }   <br>    }  <br><br>Copied!Wrap Toggled!|

## Incorrect usage of the finally block

| Description                                                                                                                                       | Example                                                                                                                                                                                                                                                                                                                                                                                                                                                                                                                                                                                                                                                                                                           |
| ------------------------------------------------------------------------------------------------------------------------------------------------- | ----------------------------------------------------------------------------------------------------------------------------------------------------------------------------------------------------------------------------------------------------------------------------------------------------------------------------------------------------------------------------------------------------------------------------------------------------------------------------------------------------------------------------------------------------------------------------------------------------------------------------------------------------------------------------------------------------------------- |
| Not handling exceptions in finally: If an exception occurs in the finally block, it may suppress exceptions thrown in the try or catch blocks.    | 1. 1<br><br>1. public class IncorrectFinallyUsage {      <br>      public static void main(String[] args) {      <br>           try {    <br>              int result = 10 / 0; // This will throw an exception    <br>           } catch (ArithmeticException e) {     <br>              System.out.println("Caught an exception: " + e.getMessage());     <br>           } finally {      <br>             int x = 10 / 0; // This will throw another exception      <br>             System.out.println("Finally block executed");     <br>        }   <br>      }   <br>    } <br><br>Copied!Wrap Toggled!                                                                                                    |
| Using return statements in finally: This can lead to unexpected behavior, as it overrides any return statements from the try or catch blocks.     | 1. 1<br><br>1. public class ReturnInFinally {      <br>      public static void main(String[] args) {    <br>          System.out.println(testMethod());    <br>      }   <br>      public static int testMethod() {    <br>         try {       <br>           return 1; // Return from try block     <br>         } catch (Exception e) {     <br>           return 2; // Return from catch block      <br>         } finally {     <br>           return 3; // This will override previous returns     <br>        }   <br>      }   <br>    }  <br><br>Copied!Wrap Toggled!                                                                                                                                   |
| Assuming finally will not execute: This is incorrect; the finally block will always execute unless the program crashes or is forcibly terminated. | 1. 1<br><br>1. public class FinallyAlwaysExecutes {      <br>      public static void main(String[] args) {     <br>          try {    <br>             System.out.println("Trying risky operation...");    <br>             int result = 10 / 0; // Throws ArithmeticException    <br>          } catch (ArithmeticException e) {      <br>             System.out.println("Caught an ArithmeticException.");     <br>             // Not exiting or terminating the program here      <br>          }      <br>         // Assuming finally won't execute (this is wrong)   <br>       }      <br>       // The finally block should be here to ensure it executes.     <br>    }  <br><br>Copied!Wrap Toggled! |
# Using Multiple Try Catch

## Basic try-catch structure

|Description|Example|
|---|---|
|Multiple try-catch blocks allow developers to handle different types of exceptions in a structured way. In Java, the basic structure of a try-catch block looks like this.|1. 1<br><br>1. try {    <br>       // Code that may throw an exception     <br>    } catch (ExceptionType e) {     <br>       // Code to handle the exception     <br>    } <br><br>Copied!Wrap Toggled!|

## Multiple try-catch

|Description|Example|
|---|---|
|Multiple try-catch refers to the use of more than one catch block within a single try statement or multiple try-catch statements in the code.|1. 1<br><br>1. public class MultipleCatchExample {   <br>      public static void main(String[] args) {      <br>        int[] numbers = {1, 2, 3};      <br>        int index = 5; // Invalid index      <br>        try {   <br>          // Trying to access an invalid index      <br>        System.out.println("Number: " + numbers[index]);    <br>        // Trying to divide by zero       <br>       int result = 10 / 0;      <br>           } catch (ArrayIndexOutOfBoundsException e) {    <br>               System.out.println("Error: Index out of bounds.");   <br>           } catch (ArithmeticException e) {   <br>               System.out.println("Error: Division by zero.");    <br>        }   <br>      }   <br>    } <br><br>Copied!Wrap Toggled!|

## Throws keyword

|Description|Example|
|---|---|
|The throws keyword is used in method declarations to indicate that a method can throw one or more exceptions.|1. 1<br><br>1. public class ThrowsExample {    <br>      public static void main(String[] args) {       <br>        try {       <br>          readFile("nonexistentfile.txt");      <br>        } catch (IOException e) {     <br>          System.out.println("Error: " + e.getMessage());       <br>        }       <br>      }    <br>      // Method that declares an exception    <br>      static void readFile(String fileName) throws IOException {    <br>        FileReader file = new FileReader(fileName);    <br>        BufferedReader fileInput = new BufferedReader(file);    <br>        // Reading the file   <br>        System.out.println(fileInput.readLine());   <br>        fileInput.close();    <br>      }   <br>    } <br><br>Copied!Wrap Toggled!|
# Checked and Runtime Exceptions Compared

## Checked exceptions

| Description                                                                                                                                         | Example                                                                                                                                                                                                                                                                                                                                                                                                                                                                                                                                                                                                                                                                                                                                                                                                                                   |
| --------------------------------------------------------------------------------------------------------------------------------------------------- | ----------------------------------------------------------------------------------------------------------------------------------------------------------------------------------------------------------------------------------------------------------------------------------------------------------------------------------------------------------------------------------------------------------------------------------------------------------------------------------------------------------------------------------------------------------------------------------------------------------------------------------------------------------------------------------------------------------------------------------------------------------------------------------------------------------------------------------------- |
| Checked exceptions are exceptions checked at compile time. They usually represent recoverable conditions, such as file not found or network issues. | 1. 1<br><br>1. import java.io.File;    <br>    import java.io.FileNotFoundException;       <br>    import java.util.Scanner;   <br>    public class CheckedExceptionExample {      <br>       public static void main(String[] args) {   <br>          try {     <br>             File myFile = new File("nonexistentfile.txt");   <br>             Scanner myReader = new Scanner(myFile);        <br>             while (myReader.hasNextLine()) {       <br>                String data = myReader.nextLine();    <br>                System.out.println(data);    <br>             }    <br>             myReader.close();     <br>       } catch (FileNotFoundException e) {    <br>             System.out.println("An error occurred: " + e.getMessage());    <br>        }   <br>      }   <br>    } <br><br>Copied!Wrap Toggled! |

## Runtime exceptions

|Description|Example|
|---|---|
|Runtime exceptions do not need to be explicitly caught or declared. They usually indicate programming errors, such as logic errors or improper use of APIs.|1. 1<br><br>1. public class RuntimeExceptionExample {     <br>      public static void main(String[] args) {      <br>        int numerator = 10;   <br>        int denominator = 0;      <br>        try {    <br>          int result = numerator / denominator; // This will cause an ArithmeticException      <br>          System.out.println("Result: " + result);    <br>        } catch (ArithmeticException e) {        <br>             System.out.println("An error occurred: Cannot divide by zero.");    <br>        }   <br>      }   <br>    }|